Workbook
Name Slicer_Branch: #N/A

Sheet Students
A1: Students
A3: Student_ID | B3: Branch | C3: Gender | D3: Age | E3: CGPA | F3: Projects_Count
A4: STU_1000 | B4: Civil | C4: Female | D4: 20 | E4: 9.15 | F4: 2
A5: STU_1001 | B5: Information Technology | C5: Female | D5: 18 | E5: 7.72 | F5: 5
A6: STU_1002 | B6: Mechanical | C6: Female | D6: 22 | E6: 5.83 | F6: 1
A7: STU_1003 | B7: Information Technology | C7: Female | D7: 20 | E7: 7.91 | F7: 2
A8: STU_1004 | B8: Information Technology | C8: Female | D8: 20 | E8: 10 | F8: 4
A9: STU_1005 | B9: Electronics | C9: Male | D9: 18 | E9: 5.75 | F9: 3
A10: STU_1006 | B10: Mechanical | C10: Female | D10: 22 | E10: 9.08 | F10: 4
A11: STU_1007 | B11: Mechanical | C11: Female | D11: 21 | E11: 6.04 | F11: 0
A12: STU_1008 | B12: Mechanical | C12: Male | D12: 22 | E12: 8.91 | F12: 2
A13: STU_1009 | B13: Information Technology | C13: Female | D13: 19 | E13: 8.67 | F13: 0
A14: STU_1010 | B14: Civil | C14: Female | D14: 23 | E14: 6.5 | F14: 0
A15: STU_1011 | B15: Mechanical | C15: Female | D15: 21 | E15: 6.63 | F15: 5
... A1003: STU_1999 | B1003: Mechanical | C1003: Male | D1003: 21 | E1003: 9.16 | F1003: 2

Sheet Skills
A1: Skills
A3: Student_ID | B3: Branch | C3: Excel_Skill | D3: SQL_Skill | E3: Tableau_Skill | F3: Python_Skill | G3: Communication_Skill
A4: STU_1000 | B4: =VLOOKUP(student_skills[[#This Row],[Student_ID]],student_data[],2,0) -> Civil | C4: 7 | D4: 1 | E4: 10 | F4: 8 | G4: 2
A5: STU_1001 | B5: =VLOOKUP(student_skills[[#This Row],[Student_ID]],student_data[],2,0) -> Information Technology | C5: 4 | D5: 8 | E5: 6 | F5: 9 | G5: 5
A6: STU_1002 | B6: =VLOOKUP(student_skills[[#This Row],[Student_ID]],student_data[],2,0) -> Mechanical | C6: 8 | D6: 4 | E6: 7 | F6: 6 | G6: 2
A7: STU_1003 | B7: =VLOOKUP(student_skills[[#This Row],[Student_ID]],student_data[],2,0) -> Information Technology | C7: 5 | D7: 4 | E7: 9 | F7: 5 | G7: 2
A8: STU_1004 | B8: =VLOOKUP(student_skills[[#This Row],[Student_ID]],student_data[],2,0) -> Information Technology | C8: 7 | D8: 5 | E8: 1 | F8: 6 | G8: 6
A9: STU_1005 | B9: =VLOOKUP(student_skills[[#This Row],[Student_ID]],student_data[],2,0) -> Electronics | C9: 10 | D9: 8 | E9: 7 | F9: 2 | G9: 10
A10: STU_1006 | B10: =VLOOKUP(student_skills[[#This Row],[Student_ID]],student_data[],2,0) -> Mechanical | C10: 3 | D10: 5 | E10: 8 | F10: 4 | G10: 9
A11: STU_1007 | B11: =VLOOKUP(student_skills[[#This Row],[Student_ID]],student_data[],2,0) -> Mechanical | C11: 7 | D11: 8 | E11: 3 | F11: 3 | G11: 4
A12: STU_1008 | B12: =VLOOKUP(student_skills[[#This Row],[Student_ID]],student_data[],2,0) -> Mechanical | C12: 8 | D12: 10 | E12: 4 | F12: 7 | G12: 6
A13: STU_1009 | B13: =VLOOKUP(student_skills[[#This Row],[Student_ID]],student_data[],2,0) -> Information Technology | C13: 5 | D13: 1 | E13: 10 | F13: 9 | G13: 7
A14: STU_1010 | B14: =VLOOKUP(student_skills[[#This Row],[Student_ID]],student_data[],2,0) -> Civil | C14: 4 | D14: 10 | E14: 6 | F14: 5 | G14: 6
A15: STU_1011 | B15: =VLOOKUP(student_skills[[#This Row],[Student_ID]],student_data[],2,0) -> Mechanical | C15: 8 | D15: 9 | E15: 10 | F15: 6 | G15: 8
... A1003: STU_1999 | B1003: =VLOOKUP(student_skills[[#This Row],[Student_ID]],student_data[],2,0) -> Mechanical | C1003: 9 | D1003: 3 | E1003: 7 | F1003: 4 | G1003: 4

Sheet Internships
A1: Internship
A3: Student_ID | B3: Internship_Count | C3: Branch | D3: Internship_Domain
A4: STU_1000 | B4: 1 | C4: =VLOOKUP(student_internships[[#This Row],[Student_ID]],student_data[],2,0) -> Civil | D4: Core Engineering
A5: STU_1001 | B5: 3 | C5: =VLOOKUP(student_internships[[#This Row],[Student_ID]],student_data[],2,0) -> Information Technology | D5: Data Analytics
A6: STU_1002 | B6: 2 | C6: =VLOOKUP(student_internships[[#This Row],[Student_ID]],student_data[],2,0) -> Mechanical | D6: Cybersecurity
A7: STU_1003 | B7: 1 | C7: =VLOOKUP(student_internships[[#This Row],[Student_ID]],student_data[],2,0) -> Information Technology | D7: Web Development
A8: STU_1004 | B8: 0 | C8: =VLOOKUP(student_internships[[#This Row],[Student_ID]],student_data[],2,0) -> Information Technology | D8: None
A9: STU_1005 | B9: 0 | C9: =VLOOKUP(student_internships[[#This Row],[Student_ID]],student_data[],2,0) -> Electronics | D9: None
A10: STU_1006 | B10: 0 | C10: =VLOOKUP(student_internships[[#This Row],[Student_ID]],student_data[],2,0) -> Mechanical | D10: None
A11: STU_1007 | B11: 2 | C11: =VLOOKUP(student_internships[[#This Row],[Student_ID]],student_data[],2,0) -> Mechanical | D11: Core Engineering
A12: STU_1008 | B12: 1 | C12: =VLOOKUP(student_internships[[#This Row],[Student_ID]],student_data[],2,0) -> Mechanical | D12: Cloud Computing
A13: STU_1009 | B13: 2 | C13: =VLOOKUP(student_internships[[#This Row],[Student_ID]],student_data[],2,0) -> Information Technology | D13: Data Science
A14: STU_1010 | B14: 0 | C14: =VLOOKUP(student_internships[[#This Row],[Student_ID]],student_data[],2,0) -> Civil | D14: None
A15: STU_1011 | B15: 3 | C15: =VLOOKUP(student_internships[[#This Row],[Student_ID]],student_data[],2,0) -> Mechanical | D15: Core Engineering
... A1003: STU_1999 | B1003: 1 | C1003: =VLOOKUP(student_internships[[#This Row],[Student_ID]],student_data[],2,0) -> Mechanical | D1003: Cloud Computing

Sheet Placements
A1: Placements
A3: Student_ID | B3: Branch | C3: Placement_Status | D3: Company | E3: Package_LPA
A4: STU_1000 | B4: =VLOOKUP(Table5[[#This Row],[Student_ID]],student_data[#All],2,0) -> Civil | C4: Placed | D4: TCS | E4: 5.4
A5: STU_1001 | B5: =VLOOKUP(Table5[[#This Row],[Student_ID]],student_data[#All],2,0) -> Information Technology | C5: Unplaced | D5: N/A | E5: 0
A6: STU_1002 | B6: =VLOOKUP(Table5[[#This Row],[Student_ID]],student_data[#All],2,0) -> Mechanical | C6: Unplaced | D6: N/A | E6: 0
A7: STU_1003 | B7: =VLOOKUP(Table5[[#This Row],[Student_ID]],student_data[#All],2,0) -> Information Technology | C7: Placed | D7: Wipro | E7: 6.06
A8: STU_1004 | B8: =VLOOKUP(Table5[[#This Row],[Student_ID]],student_data[#All],2,0) -> Information Technology | C8: Placed | D8: Wipro | E8: 5.81
A9: STU_1005 | B9: =VLOOKUP(Table5[[#This Row],[Student_ID]],student_data[#All],2,0) -> Electronics | C9: Placed | D9: Accenture | E9: 13.94
A10: STU_1006 | B10: =VLOOKUP(Table5[[#This Row],[Student_ID]],student_data[#All],2,0) -> Mechanical | C10: Placed | D10: TCS | E10: 5.21
A11: STU_1007 | B11: =VLOOKUP(Table5[[#This Row],[Student_ID]],student_data[#All],2,0) -> Mechanical | C11: Unplaced | D11: N/A | E11: 0
A12: STU_1008 | B12: =VLOOKUP(Table5[[#This Row],[Student_ID]],student_data[#All],2,0) -> Mechanical | C12: Placed | D12: TCS | E12: 6.96
A13: STU_1009 | B13: =VLOOKUP(Table5[[#This Row],[Student_ID]],student_data[#All],2,0) -> Information Technology | C13: Unplaced | D13: N/A | E13: 0
A14: STU_1010 | B14: =VLOOKUP(Table5[[#This Row],[Student_ID]],student_data[#All],2,0) -> Civil | C14: Placed | D14: Deloitte | E14: 8.28
A15: STU_1011 | B15: =VLOOKUP(Table5[[#This Row],[Student_ID]],student_data[#All],2,0) -> Mechanical | C15: Unplaced | D15: N/A | E15: 0
... A1003: STU_1999 | B1003: =VLOOKUP(Table5[[#This Row],[Student_ID]],student_data[#All],2,0) -> Mechanical | C1003: Placed | D1003: Infosys | E1003: 4.11
B1004: =VLOOKUP(Table5[[#This Row],[Student_ID]],student_data[#All],2,0) -> #N/A

Sheet Analysis
A1: ANALYSIS
A3: Student_ID | B3: Branch | C3: Employibility Score | D3: Skills Score | E3: Internship Category | F3: CGPA | G3: Project Count | H3: Internship Count | I3: Package_LPA | J3: CGPA Category
A4: STU_1000 | B4: =VLOOKUP(Table7[[#This Row],[Student_ID]],student_data[#All],2,0) -> Civil | C4: =(VLOOKUP(Table7[[#This Row],[Student_ID]],student_data[],5,0)*5)+(VLOOKUP(Table7[[#This Row],[Student_ID]],student_data[],6,0)*3)+(VLOOKUP(Table7[[#This Row],[Student_ID]],student_skills[],6,0)*2)+(VLOOKUP(Table7[[#This Row],[Student_ID]],student_internships[],2,0)*5) -> 72.75 | D4: =AVERAGE(VLOOKUP(Table7[[#This Row],[Student_ID]],student_skills[],3,0),VLOOKUP(Table7[[#This Row],[Student_ID]],student_skills[],4,0),VLOOKUP(Table7[[#This Row],[Student_ID]],student_skills[],5,0),VLOOKUP(Table7[[#This Row],[Student_ID]],student_skills[],6,0)) -> 6.5 | E4: =IF(VLOOKUP(Table7[[#This Row],[Student_ID]],student_internships[#All],2,0)>1,"EXPERIENCED",IF(VLOOKUP(Table7[[#This Row],[Student_ID]],student_internships[#All],2,0)=1,"BEGINNER","NOT EXPERIENCED")) -> BEGINNER | F4: =VLOOKUP(Table7[[#This Row],[Student_ID]],student_data[],5,0) -> 9.15 | G4: =VLOOKUP(Table7[[#This Row],[Student_ID]],student_data[#All],6,0) -> 2 | H4: =VLOOKUP(Table7[[#This Row],[Student_ID]],student_internships[],2,0) -> 1 | I4: =VLOOKUP(Table7[[#This Row],[Student_ID]],Placements!A4:E1003,5,0) -> 5.4 | J4: =IF(VLOOKUP(Table7[[#This Row],[Student_ID]],student_data[#All],5,0)>8,"HIGH",IF(VLOOKUP(Table7[[#This Row],[Student_ID]],student_data[#All],5,0)<6.5,"LOW","MEDIUM")) -> HIGH
A5: STU_1001 | B5: =VLOOKUP(Table7[[#This Row],[Student_ID]],student_data[#All],2,0) -> Information Technology | C5: =(VLOOKUP(Table7[[#This Row],[Student_ID]],student_data[],5,0)*5)+(VLOOKUP(Table7[[#This Row],[Student_ID]],student_data[],6,0)*3)+(VLOOKUP(Table7[[#This Row],[Student_ID]],student_skills[],6,0)*2)+(VLOOKUP(Table7[[#This Row],[Student_ID]],student_internships[],2,0)*5) -> 86.6 | D5: =AVERAGE(VLOOKUP(Table7[[#This Row],[Student_ID]],student_skills[],3,0),VLOOKUP(Table7[[#This Row],[Student_ID]],student_skills[],4,0),VLOOKUP(Table7[[#This Row],[Student_ID]],student_skills[],5,0),VLOOKUP(Table7[[#This Row],[Student_ID]],student_skills[],6,0)) -> 6.75 | E5: =IF(VLOOKUP(Table7[[#This Row],[Student_ID]],student_internships[#All],2,0)>1,"EXPERIENCED",IF(VLOOKUP(Table7[[#This Row],[Student_ID]],student_internships[#All],2,0)=1,"BEGINNER","NOT EXPERIENCED")) -> EXPERIENCED | F5: =VLOOKUP(Table7[[#This Row],[Student_ID]],student_data[],5,0) -> 7.72 | G5: =VLOOKUP(Table7[[#This Row],[Student_ID]],student_data[#All],6,0) -> 5 | H5: =VLOOKUP(Table7[[#This Row],[Student_ID]],student_internships[],2,0) -> 3 | I5: =VLOOKUP(Table7[[#This Row],[Student_ID]],Placements!A5:E1004,5,0) -> 0 | J5: =IF(VLOOKUP(Table7[[#This Row],[Student_ID]],student_data[#All],5,0)>8,"HIGH",IF(VLOOKUP(Table7[[#This Row],[Student_ID]],student_data[#All],5,0)<6.5,"LOW","MEDIUM")) -> MEDIUM
A6: STU_1002 | B6: =VLOOKUP(Table7[[#This Row],[Student_ID]],student_data[#All],2,0) -> Mechanical | C6: =(VLOOKUP(Table7[[#This Row],[Student_ID]],student_data[],5,0)*5)+(VLOOKUP(Table7[[#This Row],[Student_ID]],student_data[],6,0)*3)+(VLOOKUP(Table7[[#This Row],[Student_ID]],student_skills[],6,0)*2)+(VLOOKUP(Table7[[#This Row],[Student_ID]],student_internships[],2,0)*5) -> 54.15 | D6: =AVERAGE(VLOOKUP(Table7[[#This Row],[Student_ID]],student_skills[],3,0),VLOOKUP(Table7[[#This Row],[Student_ID]],student_skills[],4,0),VLOOKUP(Table7[[#This Row],[Student_ID]],student_skills[],5,0),VLOOKUP(Table7[[#This Row],[Student_ID]],student_skills[],6,0)) -> 6.25 | E6: =IF(VLOOKUP(Table7[[#This Row],[Student_ID]],student_internships[#All],2,0)>1,"EXPERIENCED",IF(VLOOKUP(Table7[[#This Row],[Student_ID]],student_internships[#All],2,0)=1,"BEGINNER","NOT EXPERIENCED")) -> EXPERIENCED | F6: =VLOOKUP(Table7[[#This Row],[Student_ID]],student_data[],5,0) -> 5.83 | G6: =VLOOKUP(Table7[[#This Row],[Student_ID]],student_data[#All],6,0) -> 1 | H6: =VLOOKUP(Table7[[#This Row],[Student_ID]],student_internships[],2,0) -> 2 | I6: =VLOOKUP(Table7[[#This Row],[Student_ID]],Placements!A6:E1005,5,0) -> 0 | J6: =IF(VLOOKUP(Table7[[#This Row],[Student_ID]],student_data[#All],5,0)>8,"HIGH",IF(VLOOKUP(Table7[[#This Row],[Student_ID]],student_data[#All],5,0)<6.5,"LOW","MEDIUM")) -> LOW
A7: STU_1003 | B7: =VLOOKUP(Table7[[#This Row],[Student_ID]],student_data[#All],2,0) -> Information Technology | C7: =(VLOOKUP(Table7[[#This Row],[Student_ID]],student_data[],5,0)*5)+(VLOOKUP(Table7[[#This Row],[Student_ID]],student_data[],6,0)*3)+(VLOOKUP(Table7[[#This Row],[Student_ID]],student_skills[],6,0)*2)+(VLOOKUP(Table7[[#This Row],[Student_ID]],student_internships[],2,0)*5) -> 60.55 | D7: =AVERAGE(VLOOKUP(Table7[[#This Row],[Student_ID]],student_skills[],3,0),VLOOKUP(Table7[[#This Row],[Student_ID]],student_skills[],4,0),VLOOKUP(Table7[[#This Row],[Student_ID]],student_skills[],5,0),VLOOKUP(Table7[[#This Row],[Student_ID]],student_skills[],6,0)) -> 5.75 | E7: =IF(VLOOKUP(Table7[[#This Row],[Student_ID]],student_internships[#All],2,0)>1,"EXPERIENCED",IF(VLOOKUP(Table7[[#This Row],[Student_ID]],student_internships[#All],2,0)=1,"BEGINNER","NOT EXPERIENCED")) -> BEGINNER | F7: =VLOOKUP(Table7[[#This Row],[Student_ID]],student_data[],5,0) -> 7.91 | G7: =VLOOKUP(Table7[[#This Row],[Student_ID]],student_data[#All],6,0) -> 2 | H7: =VLOOKUP(Table7[[#This Row],[Student_ID]],student_internships[],2,0) -> 1 | I7: =VLOOKUP(Table7[[#This Row],[Student_ID]],Placements!A7:E1006,5,0) -> 6.06 | J7: =IF(VLOOKUP(Table7[[#This Row],[Student_ID]],student_data[#All],5,0)>8,"HIGH",IF(VLOOKUP(Table7[[#This Row],[Student_ID]],student_data[#All],5,0)<6.5,"LOW","MEDIUM")) -> MEDIUM
A8: STU_1004 | B8: =VLOOKUP(Table7[[#This Row],[Student_ID]],student_data[#All],2,0) -> Information Technology | C8: =(VLOOKUP(Table7[[#This Row],[Student_ID]],student_data[],5,0)*5)+(VLOOKUP(Table7[[#This Row],[Student_ID]],student_data[],6,0)*3)+(VLOOKUP(Table7[[#This Row],[Student_ID]],student_skills[],6,0)*2)+(VLOOKUP(Table7[[#This Row],[Student_ID]],student_internships[],2,0)*5) -> 74 | D8: =AVERAGE(VLOOKUP(Table7[[#This Row],[Student_ID]],student_skills[],3,0),VLOOKUP(Table7[[#This Row],[Student_ID]],student_skills[],4,0),VLOOKUP(Table7[[#This Row],[Student_ID]],student_skills[],5,0),VLOOKUP(Table7[[#This Row],[Student_ID]],student_skills[],6,0)) -> 4.75 | E8: =IF(VLOOKUP(Table7[[#This Row],[Student_ID]],student_internships[#All],2,0)>1,"EXPERIENCED",IF(VLOOKUP(Table7[[#This Row],[Student_ID]],student_internships[#All],2,0)=1,"BEGINNER","NOT EXPERIENCED")) -> NOT EXPERIENCED | F8: =VLOOKUP(Table7[[#This Row],[Student_ID]],student_data[],5,0) -> 10 | G8: =VLOOKUP(Table7[[#This Row],[Student_ID]],student_data[#All],6,0) -> 4 | H8: =VLOOKUP(Table7[[#This Row],[Student_ID]],student_internships[],2,0) -> 0 | I8: =VLOOKUP(Table7[[#This Row],[Student_ID]],Placements!A8:E1007,5,0) -> 5.81 | J8: =IF(VLOOKUP(Table7[[#This Row],[Student_ID]],student_data[#All],5,0)>8,"HIGH",IF(VLOOKUP(Table7[[#This Row],[Student_ID]],student_data[#All],5,0)<6.5,"LOW","MEDIUM")) -> HIGH
A9: STU_1005 | B9: =VLOOKUP(Table7[[#This Row],[Student_ID]],student_data[#All],2,0) -> Electronics | C9: =(VLOOKUP(Table7[[#This Row],[Student_ID]],student_data[],5,0)*5)+(VLOOKUP(Table7[[#This Row],[Student_ID]],student_data[],6,0)*3)+(VLOOKUP(Table7[[#This Row],[Student_ID]],student_skills[],6,0)*2)+(VLOOKUP(Table7[[#This Row],[Student_ID]],student_internships[],2,0)*5) -> 41.75 | D9: =AVERAGE(VLOOKUP(Table7[[#This Row],[Student_ID]],student_skills[],3,0),VLOOKUP(Table7[[#This Row],[Student_ID]],student_skills[],4,0),VLOOKUP(Table7[[#This Row],[Student_ID]],student_skills[],5,0),VLOOKUP(Table7[[#This Row],[Student_ID]],student_skills[],6,0)) -> 6.75 | E9: =IF(VLOOKUP(Table7[[#This Row],[Student_ID]],student_internships[#All],2,0)>1,"EXPERIENCED",IF(VLOOKUP(Table7[[#This Row],[Student_ID]],student_internships[#All],2,0)=1,"BEGINNER","NOT EXPERIENCED")) -> NOT EXPERIENCED | F9: =VLOOKUP(Table7[[#This Row],[Student_ID]],student_data[],5,0) -> 5.75 | G9: =VLOOKUP(Table7[[#This Row],[Student_ID]],student_data[#All],6,0) -> 3 | H9: =VLOOKUP(Table7[[#This Row],[Student_ID]],student_internships[],2,0) -> 0 | I9: =VLOOKUP(Table7[[#This Row],[Student_ID]],Placements!A9:E1008,5,0) -> 13.94 | J9: =IF(VLOOKUP(Table7[[#This Row],[Student_ID]],student_data[#All],5,0)>8,"HIGH",IF(VLOOKUP(Table7[[#This Row],[Student_ID]],student_data[#All],5,0)<6.5,"LOW","MEDIUM")) -> LOW
A10: STU_1006 | B10: =VLOOKUP(Table7[[#This Row],[Student_ID]],student_data[#All],2,0) -> Mechanical | C10: =(VLOOKUP(Table7[[#This Row],[Student_ID]],student_data[],5,0)*5)+(VLOOKUP(Table7[[#This Row],[Student_ID]],student_data[],6,0)*3)+(VLOOKUP(Table7[[#This Row],[Student_ID]],student_skills[],6,0)*2)+(VLOOKUP(Table7[[#This Row],[Student_ID]],student_internships[],2,0)*5) -> 65.4 | D10: =AVERAGE(VLOOKUP(Table7[[#This Row],[Student_ID]],student_skills[],3,0),VLOOKUP(Table7[[#This Row],[Student_ID]],student_skills[],4,0),VLOOKUP(Table7[[#This Row],[Student_ID]],student_skills[],5,0),VLOOKUP(Table7[[#This Row],[Student_ID]],student_skills[],6,0)) -> 5 | E10: =IF(VLOOKUP(Table7[[#This Row],[Student_ID]],student_internships[#All],2,0)>1,"EXPERIENCED",IF(VLOOKUP(Table7[[#This Row],[Student_ID]],student_internships[#All],2,0)=1,"BEGINNER","NOT EXPERIENCED")) -> NOT EXPERIENCED | F10: =VLOOKUP(Table7[[#This Row],[Student_ID]],student_data[],5,0) -> 9.08 | G10: =VLOOKUP(Table7[[#This Row],[Student_ID]],student_data[#All],6,0) -> 4 | H10: =VLOOKUP(Table7[[#This Row],[Student_ID]],student_internships[],2,0) -> 0 | I10: =VLOOKUP(Table7[[#This Row],[Student_ID]],Placements!A10:E1009,5,0) -> 5.21 | J10: =IF(VLOOKUP(Table7[[#This Row],[Student_ID]],student_data[#All],5,0)>8,"HIGH",IF(VLOOKUP(Table7[[#This Row],[Student_ID]],student_data[#All],5,0)<6.5,"LOW","MEDIUM")) -> HIGH
A11: STU_1007 | B11: =VLOOKUP(Table7[[#This Row],[Student_ID]],student_data[#All],2,0) -> Mechanical | C11: =(VLOOKUP(Table7[[#This Row],[Student_ID]],student_data[],5,0)*5)+(VLOOKUP(Table7[[#This Row],[Student_ID]],student_data[],6,0)*3)+(VLOOKUP(Table7[[#This Row],[Student_ID]],student_skills[],6,0)*2)+(VLOOKUP(Table7[[#This Row],[Student_ID]],student_internships[],2,0)*5) -> 46.2 | D11: =AVERAGE(VLOOKUP(Table7[[#This Row],[Student_ID]],student_skills[],3,0),VLOOKUP(Table7[[#This Row],[Student_ID]],student_skills[],4,0),VLOOKUP(Table7[[#This Row],[Student_ID]],student_skills[],5,0),VLOOKUP(Table7[[#This Row],[Student_ID]],student_skills[],6,0)) -> 5.25 | E11: =IF(VLOOKUP(Table7[[#This Row],[Student_ID]],student_internships[#All],2,0)>1,"EXPERIENCED",IF(VLOOKUP(Table7[[#This Row],[Student_ID]],student_internships[#All],2,0)=1,"BEGINNER","NOT EXPERIENCED")) -> EXPERIENCED | F11: =VLOOKUP(Table7[[#This Row],[Student_ID]],student_data[],5,0) -> 6.04 | G11: =VLOOKUP(Table7[[#This Row],[Student_ID]],student_data[#All],6,0) -> 0 | H11: =VLOOKUP(Table7[[#This Row],[Student_ID]],student_internships[],2,0) -> 2 | I11: =VLOOKUP(Table7[[#This Row],[Student_ID]],Placements!A11:E1010,5,0) -> 0 | J11: =IF(VLOOKUP(Table7[[#This Row],[Student_ID]],student_data[#All],5,0)>8,"HIGH",IF(VLOOKUP(Table7[[#This Row],[Student_ID]],student_data[#All],5,0)<6.5,"LOW","MEDIUM")) -> LOW
A12: STU_1008 | B12: =VLOOKUP(Table7[[#This Row],[Student_ID]],student_data[#All],2,0) -> Mechanical | C12: =(VLOOKUP(Table7[[#This Row],[Student_ID]],student_data[],5,0)*5)+(VLOOKUP(Table7[[#This Row],[Student_ID]],student_data[],6,0)*3)+(VLOOKUP(Table7[[#This Row],[Student_ID]],student_skills[],6,0)*2)+(VLOOKUP(Table7[[#This Row],[Student_ID]],student_internships[],2,0)*5) -> 69.55 | D12: =AVERAGE(VLOOKUP(Table7[[#This Row],[Student_ID]],student_skills[],3,0),VLOOKUP(Table7[[#This Row],[Student_ID]],student_skills[],4,0),VLOOKUP(Table7[[#This Row],[Student_ID]],student_skills[],5,0),VLOOKUP(Table7[[#This Row],[Student_ID]],student_skills[],6,0)) -> 7.25 | E12: =IF(VLOOKUP(Table7[[#This Row],[Student_ID]],student_internships[#All],2,0)>1,"EXPERIENCED",IF(VLOOKUP(Table7[[#This Row],[Student_ID]],student_internships[#All],2,0)=1,"BEGINNER","NOT EXPERIENCED")) -> BEGINNER | F12: =VLOOKUP(Table7[[#This Row],[Student_ID]],student_data[],5,0) -> 8.91 | G12: =VLOOKUP(Table7[[#This Row],[Student_ID]],student_data[#All],6,0) -> 2 | H12: =VLOOKUP(Table7[[#This Row],[Student_ID]],student_internships[],2,0) -> 1 | I12: =VLOOKUP(Table7[[#This Row],[Student_ID]],Placements!A12:E1011,5,0) -> 6.96 | J12: =IF(VLOOKUP(Table7[[#This Row],[Student_ID]],student_data[#All],5,0)>8,"HIGH",IF(VLOOKUP(Table7[[#This Row],[Student_ID]],student_data[#All],5,0)<6.5,"LOW","MEDIUM")) -> HIGH
A13: STU_1009 | B13: =VLOOKUP(Table7[[#This Row],[Student_ID]],student_data[#All],2,0) -> Information Technology | C13: =(VLOOKUP(Table7[[#This Row],[Student_ID]],student_data[],5,0)*5)+(VLOOKUP(Table7[[#This Row],[Student_ID]],student_data[],6,0)*3)+(VLOOKUP(Table7[[#This Row],[Student_ID]],student_skills[],6,0)*2)+(VLOOKUP(Table7[[#This Row],[Student_ID]],student_internships[],2,0)*5) -> 71.35 | D13: =AVERAGE(VLOOKUP(Table7[[#This Row],[Student_ID]],student_skills[],3,0),VLOOKUP(Table7[[#This Row],[Student_ID]],student_skills[],4,0),VLOOKUP(Table7[[#This Row],[Student_ID]],student_skills[],5,0),VLOOKUP(Table7[[#This Row],[Student_ID]],student_skills[],6,0)) -> 6.25 | E13: =IF(VLOOKUP(Table7[[#This Row],[Student_ID]],student_internships[#All],2,0)>1,"EXPERIENCED",IF(VLOOKUP(Table7[[#This Row],[Student_ID]],student_internships[#All],2,0)=1,"BEGINNER","NOT EXPERIENCED")) -> EXPERIENCED | F13: =VLOOKUP(Table7[[#This Row],[Student_ID]],student_data[],5,0) -> 8.67 | G13: =VLOOKUP(Table7[[#This Row],[Student_ID]],student_data[#All],6,0) -> 0 | H13: =VLOOKUP(Table7[[#This Row],[Student_ID]],student_internships[],2,0) -> 2 | I13: =VLOOKUP(Table7[[#This Row],[Student_ID]],Placements!A13:E1012,5,0) -> 0 | J13: =IF(VLOOKUP(Table7[[#This Row],[Student_ID]],student_data[#All],5,0)>8,"HIGH",IF(VLOOKUP(Table7[[#This Row],[Student_ID]],student_data[#All],5,0)<6.5,"LOW","MEDIUM")) -> HIGH
A14: STU_1010 | B14: =VLOOKUP(Table7[[#This Row],[Student_ID]],student_data[#All],2,0) -> Civil | C14: =(VLOOKUP(Table7[[#This Row],[Student_ID]],student_data[],5,0)*5)+(VLOOKUP(Table7[[#This Row],[Student_ID]],student_data[],6,0)*3)+(VLOOKUP(Table7[[#This Row],[Student_ID]],student_skills[],6,0)*2)+(VLOOKUP(Table7[[#This Row],[Student_ID]],student_internships[],2,0)*5) -> 42.5 | D14: =AVERAGE(VLOOKUP(Table7[[#This Row],[Student_ID]],student_skills[],3,0),VLOOKUP(Table7[[#This Row],[Student_ID]],student_skills[],4,0),VLOOKUP(Table7[[#This Row],[Student_ID]],student_skills[],5,0),VLOOKUP(Table7[[#This Row],[Student_ID]],student_skills[],6,0)) -> 6.25 | E14: =IF(VLOOKUP(Table7[[#This Row],[Student_ID]],student_internships[#All],2,0)>1,"EXPERIENCED",IF(VLOOKUP(Table7[[#This Row],[Student_ID]],student_internships[#All],2,0)=1,"BEGINNER","NOT EXPERIENCED")) -> NOT EXPERIENCED | F14: =VLOOKUP(Table7[[#This Row],[Student_ID]],student_data[],5,0) -> 6.5 | G14: =VLOOKUP(Table7[[#This Row],[Student_ID]],student_data[#All],6,0) -> 0 | H14: =VLOOKUP(Table7[[#This Row],[Student_ID]],student_internships[],2,0) -> 0 | I14: =VLOOKUP(Table7[[#This Row],[Student_ID]],Placements!A14:E1013,5,0) -> 8.28 | J14: =IF(VLOOKUP(Table7[[#This Row],[Student_ID]],student_data[#All],5,0)>8,"HIGH",IF(VLOOKUP(Table7[[#This Row],[Student_ID]],student_data[#All],5,0)<6.5,"LOW","MEDIUM")) -> MEDIUM
A15: STU_1011 | B15: =VLOOKUP(Table7[[#This Row],[Student_ID]],student_data[#All],2,0) -> Mechanical | C15: =(VLOOKUP(Table7[[#This Row],[Student_ID]],student_data[],5,0)*5)+(VLOOKUP(Table7[[#This Row],[Student_ID]],student_data[],6,0)*3)+(VLOOKUP(Table7[[#This Row],[Student_ID]],student_skills[],6,0)*2)+(VLOOKUP(Table7[[#This Row],[Student_ID]],student_internships[],2,0)*5) -> 75.15 | D15: =AVERAGE(VLOOKUP(Table7[[#This Row],[Student_ID]],student_skills[],3,0),VLOOKUP(Table7[[#This Row],[Student_ID]],student_skills[],4,0),VLOOKUP(Table7[[#This Row],[Student_ID]],student_skills[],5,0),VLOOKUP(Table7[[#This Row],[Student_ID]],student_skills[],6,0)) -> 8.25 | E15: =IF(VLOOKUP(Table7[[#This Row],[Student_ID]],student_internships[#All],2,0)>1,"EXPERIENCED",IF(VLOOKUP(Table7[[#This Row],[Student_ID]],student_internships[#All],2,0)=1,"BEGINNER","NOT EXPERIENCED")) -> EXPERIENCED | F15: =VLOOKUP(Table7[[#This Row],[Student_ID]],student_data[],5,0) -> 6.63 | G15: =VLOOKUP(Table7[[#This Row],[Student_ID]],student_data[#All],6,0) -> 5 | H15: =VLOOKUP(Table7[[#This Row],[Student_ID]],student_internships[],2,0) -> 3 | I15: =VLOOKUP(Table7[[#This Row],[Student_ID]],Placements!A15:E1014,5,0) -> 0 | J15: =IF(VLOOKUP(Table7[[#This Row],[Student_ID]],student_data[#All],5,0)>8,"HIGH",IF(VLOOKUP(Table7[[#This Row],[Student_ID]],student_data[#All],5,0)<6.5,"LOW","MEDIUM")) -> MEDIUM
... A1003: STU_1999 | B1003: =VLOOKUP(Table7[[#This Row],[Student_ID]],student_data[#All],2,0) -> Mechanical | C1003: =(VLOOKUP(Table7[[#This Row],[Student_ID]],student_data[],5,0)*5)+(VLOOKUP(Table7[[#This Row],[Student_ID]],student_data[],6,0)*3)+(VLOOKUP(Table7[[#This Row],[Student_ID]],student_skills[],6,0)*2)+(VLOOKUP(Table7[[#This Row],[Student_ID]],student_internships[],2,0)*5) -> 64.8 | D1003: =AVERAGE(VLOOKUP(Table7[[#This Row],[Student_ID]],student_skills[],3,0),VLOOKUP(Table7[[#This Row],[Student_ID]],student_skills[],4,0),VLOOKUP(Table7[[#This Row],[Student_ID]],student_skills[],5,0),VLOOKUP(Table7[[#This Row],[Student_ID]],student_skills[],6,0)) -> 5.75 | E1003: =IF(VLOOKUP(Table7[[#This Row],[Student_ID]],student_internships[#All],2,0)>1,"EXPERIENCED",IF(VLOOKUP(Table7[[#This Row],[Student_ID]],student_internships[#All],2,0)=1,"BEGINNER","NOT EXPERIENCED")) -> BEGINNER | F1003: =VLOOKUP(Table7[[#This Row],[Student_ID]],student_data[],5,0) -> 9.16 | G1003: =VLOOKUP(Table7[[#This Row],[Student_ID]],student_data[#All],6,0) -> 2 | H1003: =VLOOKUP(Table7[[#This Row],[Student_ID]],student_internships[],2,0) -> 1 | I1003: =VLOOKUP(Table7[[#This Row],[Student_ID]],Placements!A1003:E2002,5,0) -> 4.11 | J1003: =IF(VLOOKUP(Table7[[#This Row],[Student_ID]],student_data[#All],5,0)>8,"HIGH",IF(VLOOKUP(Table7[[#This Row],[Student_ID]],student_data[#All],5,0)<6.5,"LOW","MEDIUM")) -> HIGH

Sheet Pivot Table
A3: Row Labels | B3: Count of Student_ID | C3: Average of CGPA | D3: Average of Project Count
A4: Civil | B4: 206 | C4: 7.814466 | D4: 2.5631068 | H4: no of students | I4: =SUM(B4:B8) -> 1000
A5: Computer Science | B5: 210 | C5: 7.5794762 | D5: 2.4809524 | H5: no of branches | I5: =COUNT(B4:B8) -> 5
A6: Electronics | B6: 190 | C6: 7.4174211 | D6: 2.6210526 | H6: avg cgpa | I6: =AVERAGE(C4:C8) -> 7.5897398
A7: Information Technology | B7: 204 | C7: 7.6554412 | D7: 2.5441176 | H7: avg projects | I7: =AVERAGE(D4:D8) -> 2.5744775
A8: Mechanical | B8: 190 | C8: 7.4818947 | D8: 2.6631579 | H8: avg skill score | I8: =AVERAGE(D23:D27) -> 5.4529221
H9: total interns | I9: =SUM(C31:C35) -> 1069
H10: total paced | I10: =F40 -> 779
H11: avg package | I11: =AVERAGE(C40:C44) -> 4.2942795
H12: highest package | I12: =MAX(D40:D44) -> 39.06
H13: avg employbility score | I13: =AVERAGE(C23:C27) -> 61.840158
H14: placement percentage | I14: =I10/I4 -> 0.779
A22: Row Labels | B22: Count of Student_ID | C22: Average of Employibility Score | D22: Average of Skills Score
A23: Civil | B23: 206 | C23: 62.489806 | D23: 5.3980583
A24: Computer Science | B24: 210 | C24: 61.425952 | D24: 5.2214286
A25: Electronics | B25: 190 | C25: 61.508158 | D25: 5.6855263
A26: Information Technology | B26: 204 | C26: 62.767402 | D26: 5.4411765
A27: Mechanical | B27: 190 | C27: 61.009474 | D27: 5.5184211
A30: Row Labels | B30: Count of Student_ID | C30: Sum of Internship Count
A31: Civil | B31: 206 | C31: 198
A32: Computer Science | B32: 210 | C32: 240
A33: Electronics | B33: 190 | C33: 198
A34: Information Technology | B34: 204 | C34: 243
A35: Mechanical | B35: 190 | C35: 190
F37: Placement_Status | G37: Placed
A39: Row Labels | B39: Count of Student_ID | C39: Average of Package_LPA | D39: Max. of Package_LPA2 | F39: Count of Student_ID
A40: Civil | B40: 206 | C40: 4.2715534 | D40: 39.06 | F40: 779
A41: Computer Science | B41: 210 | C41: 3.941381 | D41: 14.61
A42: Electronics | B42: 190 | C42: 4.7614737 | D42: 36.56
A43: Information Technology | B43: 204 | C43: 4.0915686 | D43: 34.45
A44: Mechanical | B44: 190 | C44: 4.4054211 | D44: 25.43
A49: Row Labels | B49: Average of CGPA | D49: Row Labels | E49: Average of Project Count | G49: Row Labels | H49: Sum of Internship Count
A50: Civil | B50: 7.814466 | D50: Civil | E50: 2.5631068 | G50: Civil | H50: 198
A51: Computer Science | B51: 7.5794762 | D51: Computer Science | E51: 2.4809524 | G51: Computer Science | H51: 240
A52: Electronics | B52: 7.4174211 | D52: Electronics | E52: 2.6210526 | G52: Electronics | H52: 198
A53: Information Technology | B53: 7.6554412 | D53: Information Technology | E53: 2.5441176 | G53: Information Technology | H53: 243
A54: Mechanical | B54: 7.4818947 | D54: Mechanical | E54: 2.6631579 | G54: Mechanical | H54: 190
A55: Grand Total | B55: 7.59405 | D55: Grand Total | E55: 2.572 | G55: Grand Total | H55: 1069
A59: Row Labels | B59: Average of Package_LPA
A60: Civil | B60: 4.2715534
...

Sheet Dashboard
